{"name": "test_not_authorized_not_existing_user", "status": "failed", "statusDetails": {"message": "AssertionError", "trace": "def test_not_authorized_not_existing_user():\n        s_token = session.encode_session(SessionData())\n>       GetAuth(session_token=s_token).request().verify()\n\ntests/enduser/test_auth.py:26: \n_ _ _ _ _ _ _ _ _ _ _ _ _ _ _ _ _ _ _ _ _ _ _ _ _ _ _ _ _ _ _ _ _ _ _ _ _ _ _ _ _ _ _ _ _ _ _ _ _ _ _ _ _ _ _ _ _ _\nqa/api/enduser/calls.py:20: in verify\n    self.verify_response(resp_body=resp_body)\n_ _ _ _ _ _ _ _ _ _ _ _ _ _ _ _ _ _ _ _ _ _ _ _ _ _ _ _ _ _ _ _ _ _ _ _ _ _ _ _ _ _ _ _ _ _ _ _ _ _ _ _ _ _ _ _ _ _\n\nself = <qa.api.enduser.calls.GetAuth object at 0x10423a4f0>, error_code = None, resp_body = {'anonymous': True}\nignore_order = False, exclude_paths = None, normalize = False\n\n    def verify_response(self, error_code=None, resp_body=None,\n                        ignore_order=False, exclude_paths=None,\n                        normalize=False):\n        if error_code:\n            assert self.response.status_code == error_code, (\n                f'Unexpected code: {self.response.status_code}'\n            )\n        else:\n>           assert self.response.status_code == 200\nE           AssertionError\n\nqa/tools/caller.py:87: AssertionError"}, "start": 1648640656008, "stop": 1648640656376, "uuid": "cae80898-bc2c-4462-a777-9ca43b9551ec", "historyId": "98ccee3499e5684c359c1a886a1cba33", "testCaseId": "3fd93247308aeed0356321be7c311e43", "fullName": "tests.enduser.test_auth#test_not_authorized_not_existing_user", "labels": [{"name": "parentSuite", "value": "tests.enduser"}, {"name": "suite", "value": "test_auth"}, {"name": "host", "value": "Elenas-MacBook-Pro.local"}, {"name": "thread", "value": "59719-MainThread"}, {"name": "framework", "value": "pytest"}, {"name": "language", "value": "cpython3"}, {"name": "package", "value": "tests.enduser.test_auth"}]}