{"name": "test_no_enduser_auth", "status": "failed", "statusDetails": {"message": "AssertionError: Unexpected code: 500", "trace": "def test_no_enduser_auth():\n        org = orgs_tbl.insert()\n        user = endusers_tbl.insert(org_id=org.Id.value)\n>       PostLogin(user=user).request().verify(failed=True)\n\ntests/enduser/test_login.py:24: \n_ _ _ _ _ _ _ _ _ _ _ _ _ _ _ _ _ _ _ _ _ _ _ _ _ _ _ _ _ _ _ _ _ _ _ _ _ _ _ _ _ _ _ _ _ _ _ _ _ _ _ _ _ _ _ _ _ _\nqa/api/enduser/calls.py:34: in verify\n    self.verify_response(\n_ _ _ _ _ _ _ _ _ _ _ _ _ _ _ _ _ _ _ _ _ _ _ _ _ _ _ _ _ _ _ _ _ _ _ _ _ _ _ _ _ _ _ _ _ _ _ _ _ _ _ _ _ _ _ _ _ _\n\nself = <qa.api.enduser.calls.PostLogin object at 0x1041fdc10>, error_code = 403, resp_body = {'successful': False}\nignore_order = False, exclude_paths = None, normalize = False\n\n    def verify_response(self, error_code=None, resp_body=None,\n                        ignore_order=False, exclude_paths=None,\n                        normalize=False):\n        if error_code:\n>           assert self.response.status_code == error_code, (\n                f'Unexpected code: {self.response.status_code}'\n            )\nE           AssertionError: Unexpected code: 500\n\nqa/tools/caller.py:83: AssertionError"}, "start": 1648640664312, "stop": 1648640664694, "uuid": "5ee63801-12e9-4aa0-baf5-fd7425ad8c3f", "historyId": "2395bde7371fc6624a57680d378c7c01", "testCaseId": "a7ef53694fe104675c12fc80567d4f35", "fullName": "tests.enduser.test_login#test_no_enduser_auth", "labels": [{"name": "parentSuite", "value": "tests.enduser"}, {"name": "suite", "value": "test_login"}, {"name": "host", "value": "Elenas-MacBook-Pro.local"}, {"name": "thread", "value": "59719-MainThread"}, {"name": "framework", "value": "pytest"}, {"name": "language", "value": "cpython3"}, {"name": "package", "value": "tests.enduser.test_login"}]}