{"name": "test_password_mismatch", "status": "failed", "statusDetails": {"message": "AssertionError: Unexpected code: 500", "trace": "def test_password_mismatch():\n        org = orgs_tbl.insert()\n        user = endusers_tbl.insert(org_id=org.Id.value)\n        endusers_tbl.insert_auth(user_id=user.Id.value)\n>       PostLogin(user=user).request().verify(failed=True)\n\ntests/enduser/test_login.py:32: \n_ _ _ _ _ _ _ _ _ _ _ _ _ _ _ _ _ _ _ _ _ _ _ _ _ _ _ _ _ _ _ _ _ _ _ _ _ _ _ _ _ _ _ _ _ _ _ _ _ _ _ _ _ _ _ _ _ _\nqa/api/enduser/calls.py:34: in verify\n    self.verify_response(\n_ _ _ _ _ _ _ _ _ _ _ _ _ _ _ _ _ _ _ _ _ _ _ _ _ _ _ _ _ _ _ _ _ _ _ _ _ _ _ _ _ _ _ _ _ _ _ _ _ _ _ _ _ _ _ _ _ _\n\nself = <qa.api.enduser.calls.PostLogin object at 0x104223160>, error_code = 403, resp_body = {'successful': False}\nignore_order = False, exclude_paths = None, normalize = False\n\n    def verify_response(self, error_code=None, resp_body=None,\n                        ignore_order=False, exclude_paths=None,\n                        normalize=False):\n        if error_code:\n>           assert self.response.status_code == error_code, (\n                f'Unexpected code: {self.response.status_code}'\n            )\nE           AssertionError: Unexpected code: 500\n\nqa/tools/caller.py:83: AssertionError"}, "start": 1648640664710, "stop": 1648640665235, "uuid": "e21a0d9f-5abb-41f1-ab95-648d2254a67c", "historyId": "cd27ba0d11d9ba46a2c28ffa2992aff5", "testCaseId": "58d4f927a235e491fd9fce6c274c66dd", "fullName": "tests.enduser.test_login#test_password_mismatch", "labels": [{"name": "parentSuite", "value": "tests.enduser"}, {"name": "suite", "value": "test_login"}, {"name": "host", "value": "Elenas-MacBook-Pro.local"}, {"name": "thread", "value": "59719-MainThread"}, {"name": "framework", "value": "pytest"}, {"name": "language", "value": "cpython3"}, {"name": "package", "value": "tests.enduser.test_login"}]}