{"name": "test_user_not_exists", "status": "failed", "statusDetails": {"message": "AssertionError: Unexpected code: 500", "trace": "def test_user_not_exists():\n>       PostLogin().request().verify(failed=True)\n\ntests/enduser/test_login.py:18: \n_ _ _ _ _ _ _ _ _ _ _ _ _ _ _ _ _ _ _ _ _ _ _ _ _ _ _ _ _ _ _ _ _ _ _ _ _ _ _ _ _ _ _ _ _ _ _ _ _ _ _ _ _ _ _ _ _ _\nqa/api/enduser/calls.py:34: in verify\n    self.verify_response(\n_ _ _ _ _ _ _ _ _ _ _ _ _ _ _ _ _ _ _ _ _ _ _ _ _ _ _ _ _ _ _ _ _ _ _ _ _ _ _ _ _ _ _ _ _ _ _ _ _ _ _ _ _ _ _ _ _ _\n\nself = <qa.api.enduser.calls.PostLogin object at 0x1042b0640>, error_code = 403, resp_body = {'successful': False}\nignore_order = False, exclude_paths = None, normalize = False\n\n    def verify_response(self, error_code=None, resp_body=None,\n                        ignore_order=False, exclude_paths=None,\n                        normalize=False):\n        if error_code:\n>           assert self.response.status_code == error_code, (\n                f'Unexpected code: {self.response.status_code}'\n            )\nE           AssertionError: Unexpected code: 500\n\nqa/tools/caller.py:83: AssertionError"}, "start": 1648640663920, "stop": 1648640664295, "uuid": "ed3f6040-2eb6-4ab8-ae60-9bd38570b5ab", "historyId": "1f9dfd66672c73b46bd461390f026237", "testCaseId": "98f709e224a31f9b0f00c234968753fa", "fullName": "tests.enduser.test_login#test_user_not_exists", "labels": [{"name": "parentSuite", "value": "tests.enduser"}, {"name": "suite", "value": "test_login"}, {"name": "host", "value": "Elenas-MacBook-Pro.local"}, {"name": "thread", "value": "59719-MainThread"}, {"name": "framework", "value": "pytest"}, {"name": "language", "value": "cpython3"}, {"name": "package", "value": "tests.enduser.test_login"}]}