{"name": "test_ticket_body[second]", "status": "broken", "statusDetails": {"message": "ConnectionRefusedError: [Errno 61] Connection refused", "trace": "@pytest.fixture(scope='module', autouse=True)\n    def tickets():\n        tickets = Tickets(number=2)\n>       window = TaggingWindow(tickets=tickets).mock()\n\ntests/tagging_ui/tagging_tickets/test_tickets_view.py:14: \n_ _ _ _ _ _ _ _ _ _ _ _ _ _ _ _ _ _ _ _ _ _ _ _ _ _ _ _ _ _ _ _ _ _ _ _ _ _ _ _ _ _ _ _ _ _ _ _ _ _ _ _ _ _ _ _ _ _\ntests/tagging_ui/tagging_tickets/tagging_window.py:94: in mock\n    api.GetTaggingWindow.fe_reply(\nqa/tools/request.py:116: in fe_reply\n    return cls.reply(\nqa/tools/request.py:88: in reply\n    return MockServer().reply(\nqa/tools/mock.py:31: in reply\n    self.reset(name)\nqa/tools/mock.py:25: in reset\n    self.get_client(name).reset()\nqa/tools/mock.py:17: in get_client\n    return HTTPMock(\n.venv/lib/python3.9/site-packages/pretenders/client/http.py:49: in __init__\n    super(HTTPMock, self).__init__(host, port, timeout, name)\n.venv/lib/python3.9/site-packages/pretenders/client/__init__.py:102: in __init__\n    self.pretender_details = self._request_mock_access()\n.venv/lib/python3.9/site-packages/pretenders/client/__init__.py:152: in _request_mock_access\n    response, data = self.boss_access.http('POST',\n.venv/lib/python3.9/site-packages/pretenders/client/__init__.py:39: in http\n    response = self._get_response(method, *args, **kwargs)\n.venv/lib/python3.9/site-packages/pretenders/client/__init__.py:27: in _get_response\n    self.connection.request(method=method, *args, **kwargs)\n/Library/Frameworks/Python.framework/Versions/3.9/lib/python3.9/http/client.py:1285: in request\n    self._send_request(method, url, body, headers, encode_chunked)\n/Library/Frameworks/Python.framework/Versions/3.9/lib/python3.9/http/client.py:1331: in _send_request\n    self.endheaders(body, encode_chunked=encode_chunked)\n/Library/Frameworks/Python.framework/Versions/3.9/lib/python3.9/http/client.py:1280: in endheaders\n    self._send_output(message_body, encode_chunked=encode_chunked)\n/Library/Frameworks/Python.framework/Versions/3.9/lib/python3.9/http/client.py:1040: in _send_output\n    self.send(msg)\n/Library/Frameworks/Python.framework/Versions/3.9/lib/python3.9/http/client.py:980: in send\n    self.connect()\n/Library/Frameworks/Python.framework/Versions/3.9/lib/python3.9/http/client.py:946: in connect\n    self.sock = self._create_connection(\n/Library/Frameworks/Python.framework/Versions/3.9/lib/python3.9/socket.py:844: in create_connection\n    raise err\n_ _ _ _ _ _ _ _ _ _ _ _ _ _ _ _ _ _ _ _ _ _ _ _ _ _ _ _ _ _ _ _ _ _ _ _ _ _ _ _ _ _ _ _ _ _ _ _ _ _ _ _ _ _ _ _ _ _\n\naddress = ('localhost', 8088), timeout = <object object at 0x101b14540>, source_address = None\n\n    def create_connection(address, timeout=_GLOBAL_DEFAULT_TIMEOUT,\n                          source_address=None):\n        \"\"\"Connect to *address* and return the socket object.\n    \n        Convenience function.  Connect to *address* (a 2-tuple ``(host,\n        port)``) and return the socket object.  Passing the optional\n        *timeout* parameter will set the timeout on the socket instance\n        before attempting to connect.  If no *timeout* is supplied, the\n        global default timeout setting returned by :func:`getdefaulttimeout`\n        is used.  If *source_address* is set it must be a tuple of (host, port)\n        for the socket to bind as a source address before making the connection.\n        A host of '' or port 0 tells the OS to use the default.\n        \"\"\"\n    \n        host, port = address\n        err = None\n        for res in getaddrinfo(host, port, 0, SOCK_STREAM):\n            af, socktype, proto, canonname, sa = res\n            sock = None\n            try:\n                sock = socket(af, socktype, proto)\n                if timeout is not _GLOBAL_DEFAULT_TIMEOUT:\n                    sock.settimeout(timeout)\n                if source_address:\n                    sock.bind(source_address)\n>               sock.connect(sa)\nE               ConnectionRefusedError: [Errno 61] Connection refused\n\n/Library/Frameworks/Python.framework/Versions/3.9/lib/python3.9/socket.py:832: ConnectionRefusedError"}, "parameters": [{"name": "ticket", "value": "1"}], "start": 1648636893076, "stop": 1648636893076, "uuid": "aa8806e0-d1fe-423a-add1-6fe92a45ecb6", "historyId": "2b8518aeb4eb22fd9bf5766d63aed91b", "testCaseId": "0aa586b51ceb655829d952a4a7bc60e0", "fullName": "tests.tagging_ui.tagging_tickets.test_tickets_view#test_ticket_body", "labels": [{"name": "parentSuite", "value": "tests.tagging_ui.tagging_tickets"}, {"name": "suite", "value": "test_tickets_view"}, {"name": "host", "value": "Elenas-MacBook-Pro.local"}, {"name": "thread", "value": "16629-MainThread"}, {"name": "framework", "value": "pytest"}, {"name": "language", "value": "cpython3"}, {"name": "package", "value": "tests.tagging_ui.tagging_tickets.test_tickets_view"}]}